<?xml version="1.0" ?>
<!-- =================================================================================== -->
<!-- |    This document was autogenerated by xacro from irb1200_7_70.xacro             | -->
<!-- |    EDITING THIS FILE BY HAND IS NOT RECOMMENDED                                 | -->
<!-- =================================================================================== -->
<robot name="abb_irb1200_7_70">
  <!-- Conversion were obtained from http://www.e-paint.co.uk/Lab_values.asp
       unless otherwise stated. -->

  <material name="white">
    <color rgba="1 1 1 1"/>
  </material>

  <material name="gray">
    <color rgba="0.7 0.7 0.7 1"/>
  </material>

    <material name="black">
    <color rgba="0 0 0 1"/>
  </material>

  <material name="red">
    <color rgba="1 0 0 1"/>
  </material>

  <material name="blue">
    <color rgba="0.180 0.46 0.594 1"/>
  </material>

  <!-- link list -->
  <link name="base_link">
      <inertial>
        <mass value="13.7742"/>
        <inertia ixx="0.101998" ixy="0.000495482" ixz="0.000311158" iyy="0.13969" iyz="-0.000245375" izz="0.130433"/>
      </inertial>
    <collision name="collision">
      <geometry>
        <mesh filename="package://meshes/irb1200_5_90/collision/base_link.stl"/>
      </geometry>
    </collision>
    <visual name="visual">
      <geometry>
        <mesh filename="package://meshes/irb1200_5_90/visual/base_link.dae"/>
      </geometry>
    <material name="gray"/>
    </visual>
  </link>

  <link name="link_1">
    <inertial>
        <mass value="11.8419"/>
        <inertia ixx="0.11194" ixy="-4.54988e-05" ixz="0.000280961" iyy="0.0915159" iyz="-0.000109905" izz="0.0876456"/>
    </inertial>
    <collision name="collision">
      <geometry>
        <mesh filename="package://meshes/irb1200_5_90/collision/link_1.stl"/>
      </geometry>
    </collision>
    <visual name="visual">
      <geometry>
        <mesh filename="package://meshes/irb1200_5_90/visual/link_1.dae"/>
      </geometry>
    <material name="white"/>
    </visual>
  </link>
  <link name="link_2">
     <!-- uncertain inertial-->
     <inertial>
        <mass value="11.8419"/>
        <inertia ixx="0.11194" ixy="-4.54988e-05" ixz="0.000280961" iyy="0.0915159" iyz="-0.000109905" izz="0.0876456"/>
    </inertial>
    <collision name="collision">
      <geometry>
        <mesh filename="package://meshes/irb1200_7_70/collision/link_2.stl"/>
      </geometry>
    </collision>
    <visual name="visual">
      <geometry>
        <mesh filename="package://meshes/irb1200_7_70/visual/link_2.dae"/>
      </geometry>
    <material name="gray"/>
    </visual>
  </link>
  <link name="link_3">
    <!-- uncertain inertial-->
      <inertial>
        <mass value="11.8419"/>
        <inertia ixx="0.11194" ixy="-4.54988e-05" ixz="0.000280961" iyy="0.0915159" iyz="-0.000109905" izz="0.0876456"/>
    </inertial>
    <collision name="graphite_white">
      <geometry>
        <mesh filename="package://meshes/irb1200_7_70/collision/link_3.stl"/>
      </geometry>
    </collision>
    <visual name="visual">
      <geometry>
        <mesh filename="package://meshes/irb1200_7_70/visual/link_3.dae"/>
      </geometry>
    <material name="white"/>
    </visual>
  </link>
  <link name="link_4">
    <inertial>
      <mass value="2.74436"/>
      <inertia ixx="0.00573099" ixy="-0.000131119" ixz="0.000380232" iyy="0.0118352" iyz="-2.26565e-05" izz="0.0114428"/>
    </inertial>
    <collision name="collision">
      <!-- offset purely to allow reuse of meshes -->
      <origin rpy="0 0 0" xyz="-0.1 0 0"/>
      <geometry>
        <mesh filename="package://meshes/irb1200_5_90/collision/link_4.stl"/>
      </geometry>
    </collision>
    <visual name="visual">
      <!-- offset purely to allow reuse of meshes -->
      <origin rpy="0 0 0" xyz="-0.1 0 0"/>
      <geometry>
        <mesh filename="package://meshes/irb1200_5_90/visual/link_4.dae"/>
      </geometry>
    <material name="white"/>
    </visual>
  </link>
  <link name="link_5">
    <inertial>
      <mass value="0.62953"/>
      <inertia ixx="0.000502815" ixy="-1.03173e-05" ixz="-8.74347e-08" iyy="0.00108856" iyz="2.07657e-07" izz="0.000918873"/>
    </inertial>
    <collision name="collision">
      <geometry>
        <mesh filename="package://meshes/irb1200_5_90/collision/link_5.stl"/>
      </geometry>
    </collision>
    <visual name="visual">
      <geometry>
        <mesh filename="package://meshes/irb1200_5_90/visual/link_5.dae"/>
      </geometry>
    <material name="gray"/>
    </visual>
  </link>
  <link name="link_6">
    <inertial>
      <mass value="0.137"/>
      <inertia ixx="0.001" ixy="0" ixz="0" iyy="0.001" iyz="0" izz="0.001"/>
    </inertial>
    <collision name="collision">
      <geometry>
        <mesh filename="package://meshes/irb1200_5_90/collision/link_6.stl"/>
      </geometry>
    </collision>
    <visual name="visual">
      <geometry>
        <mesh filename="package://meshes/irb1200_5_90/visual/link_6.dae"/>
      </geometry>
    <material name="gray"/>
    </visual>
  </link>
  <link name="flange">
      <inertial>
      <origin xyz="0 0 0"/>
      <mass value="0.1"/>
      <inertia ixx="5" ixy="0" ixz="0" iyy="5" iyz="0" izz="5"/>
    </inertial>
    <collision name="collision">
      <origin xyz="0 0 0"/>
      <geometry>
        <cylinder length="0.01" radius="0.01"/>
      </geometry>
    </collision>
    <visual name="visual">
      <geometry>
        <cylinder length="0.01" radius="0.01"/>
      </geometry>        
      <origin xyz="0 0 0"/>
      <material name ="white"/>
    </visual>
  </link>
  <!-- end of link list -->
  <!-- joint list -->
  <joint name="joint_1" type="revolute">
    <origin rpy="0 0 0" xyz="0 0 0.3991"/>
    <axis xyz="0 0 1"/>
    <parent link="base_link"/>
    <child link="link_1"/>
    <limit effort="0" lower="-2.967" upper="2.967" velocity="5.027"/>
  </joint>
  <joint name="joint_2" type="revolute">
    <origin rpy="0 0 0" xyz="0 0 0"/>
    <axis xyz="0 1 0"/>
    <parent link="link_1"/>
    <child link="link_2"/>
    <limit effort="0" lower="-1.745" upper="2.356" velocity="4.189"/>
  </joint>
  <joint name="joint_3" type="revolute">
    <origin rpy="0 0 0" xyz="0 0 0.350"/>
    <axis xyz="0 1 0"/>
    <parent link="link_2"/>
    <child link="link_3"/>
    <limit effort="0" lower="-3.491" upper="1.222" velocity="5.236"/>
  </joint>
  <joint name="joint_4" type="revolute">
    <origin rpy="0 0 0" xyz="0 0 0.042"/>
    <axis xyz="1 0 0"/>
    <parent link="link_3"/>
    <child link="link_4"/>
    <limit effort="0" lower="-4.712" upper="4.712" velocity="6.981"/>
  </joint>
  <joint name="joint_5" type="revolute">
    <origin rpy="0 0 0" xyz="0.351 0 0 "/>
    <axis xyz="0 1 0"/>
    <parent link="link_4"/>
    <child link="link_5"/>
    <limit effort="0" lower="-2.269" upper="2.269" velocity="7.069"/>
  </joint>
  <joint name="joint_6" type="fixed">
    <origin rpy="0 0 0" xyz="0.082 0 0 "/>
    <axis xyz="1 0 0"/>
    <parent link="link_5"/>
    <child link="link_6"/>
    <limit effort="0" lower="-6.283" upper="6.283" velocity="10.472"/>
  </joint>
  <joint name="joint_6-flange" type="fixed">
    <origin rpy="0 0 0" xyz="0 0 0"/>
    <parent link="link_6"/>
    <child link="flange"/>
  </joint>

  <!-- ROS-Industrial 'flange' frame: attachment point for EEF models -->
  <!-- ROS-Industrial 'tool0' frame: all-zeros tool frame -->
  <joint name="link_6-tool0" type="fixed">
    <origin rpy="0 1.5707963267948966 0" xyz="-0.0075 0 0"/>
    <parent link="flange"/>
    <child link="tool0"/>
  </joint>

  <joint name="tool0-tip" type="fixed">
    <origin rpy="0 0 0" xyz="0 0 0.2065"/>
    <parent link="tool0"/>
    <child link="tip0"/>
  </joint>

  <!-- end of joint list -->

  <link name="tool0">
      <inertial>
      <origin xyz="0 0 0" rpy="0 0 0"/>
      <mass value="0.1"/>
      <inertia ixx="0.01" ixy="0" ixz="0" iyy="0.01" iyz="0" izz="0.01"/>
    </inertial>
    <collision name="collision">
      <origin xyz="0 0 0" rpy="0 0 0"/>
      <contact_coefficients mu = "0.5" kp = "1e8" kd = "1e8"/>
      <lateral_friction value="0.18"/>
      <geometry>
        <mesh filename="package://meshes/rod.stl" />
      </geometry>

    </collision>
    <visual name="visual">
      <origin xyz="0 0 0" rpy="0 0 0"/>
      <geometry>
          <mesh filename="package://meshes/rod.stl" />
      </geometry>        
      <material name ="blue"/>
    </visual>
  </link>

  <link name="tip0">
    <inertial>
      <mass value="0.001"/>
      <inertia ixx="0.001" ixy="0" ixz="0" iyy="0.001" iyz="0" izz="0.001"/>
    </inertial>
  </link>

</robot>

